Workbook

Sheet 使用方法
A1: =_xlfn.DISPIMG("ID_700D93C647864831B6AA43D20FD41A57",1) -> =DISPIMG("ID_700D93C647864831B6AA43D20FD41A57",1) | D1: =_xlfn.DISPIMG("ID_AB1FC7A41AB444DC945223AF36ECC834",1) -> =DISPIMG("ID_AB1FC7A41AB444DC945223AF36ECC834",1) | G1: =_xlfn.DISPIMG("ID_BF1A26ED33B1423BB38B8907770EE224",1) -> =DISPIMG("ID_BF1A26ED33B1423BB38B8907770EE224",1)
A21: 有任何问题随时联系：xhs@朱年北；dy号：zhunianbei

Sheet 课题进度
A1: 精灵编号 | B1: 精灵名称 | C1: 系别 | D1: 图鉴课题总数 | E1: 完成进度 | F1: 课题类别 | G1: 课题内容 | H1: 完成情况 | I1: 备注 | J1: 词条新增时间
A2: N.001 | B2: 迪莫 | C2: 光 | D2: 7 | E2: =SUM(H2:H8)/D2 -> 0 | F2: 捕捉 | G2: 捕捉1只精灵 | H2: 0 | I2: 开服必送 | J2: S1
F3: 天分 | G3: 捕捉1只了不起天分的精灵 | H3: 0 | J3: S1
F4: 亲密度 | G4: 使迪莫的亲密度等级达到5级 | H4: 0 | J4: S1
F5: 奖牌 | G5: 获得「命定勇者」奖牌 | H5: 0 | J5: S1
F6: 技能 | G6: 使用1次【闪光】 | H6: 0 | J6: S1
F7: 技能 | G7: 使用1次【光刃】 | H7: 0 | J7: S1
F8: 首领 | G8: 使用进化之力，将精灵进化为首领 | H8: 0 | I8: 推进洛克里安主线剧情至第五章结束获得首领信物「至尊光戒」，在巨人裂谷的火巨人、森巨人、雪巨人守护地分别获得首领信物「原初之火」、「原初之草」、「原初之水」 | J8: S3-第一版
A9: N.002 | B9: 喵喵 | C9: 草 | D9: 3 | E9: =SUM(H9:H11)/D9 -> 0 | F9: 捕捉 | G9: 捕捉1只精灵 | H9: 0 | I9: 一代御三家，没选的可以在其他人世界抓 | J9: S1
F10: 天分 | G10: 捕捉1只了不起天分的精灵 | H10: 0 | J10: S1
F11: 进化 | G11: 使精灵成功进化1次 | H11: 0 | I11: 16级进化 | J11: S1
A12: N.003 | B12: 喵呜 | C12: 草 | D12: 3 | E12: =SUM(H12:H14)/D12 -> 0 | F12: 捕捉 | G12: 捕捉1只精灵 | H12: 0 | I12: 一代御三家，没选的可以在其他人世界抓 | J12: S1
F13: 天分 | G13: 捕捉1只了不起天分的精灵 | H13: 0 | J13: S1
F14: 进化 | G14: 使精灵成功进化1次 | H14: 0 | I14: 32级进化 | J14: S1
A15: N.004 | B15: 魔力猫 | C15: 草 | D15: 7 | E15: =SUM(H15:H21)/D15 -> 0 | F15: 捕捉 | G15: 捕捉1只精灵 | H15: 0 | I15: 一代御三家，没选的可以在其他人世界抓 | J15: S1
F16: 天分 | G16: 捕捉1只了不起天分的精灵 | H16: 0 | J16: S1
F17: 炫彩 | G17: 捕捉1只炫彩突变的精灵 | H17: 0 | J17: S1
F18: 首领 | G18: 使用进化之力，将精灵进化为首领 | H18: 0 | I18: 完成魔法学院初始精灵首领挑战，获得首领信物「阳光罐头」，进化为叶冕魔力猫 | J18: S1
F19: 奖牌 | G19: 获得「命定勇者」奖牌 | H19: 0 | J19: S1
F20: 技能 | G20: 使用2次【棘突】 | H20: 0 | J20: S1
F21: 技能 | G21: 使用3次【光合作用】 | H21: 0 | J21: S1
A22: N.005 | B22: 火花 | C22: 火 | D22: 3 | E22: =SUM(H22:H24)/D22 -> 0 | F22: 捕捉 | G22: 捕捉1只精灵 | H22: 0 | I22: 一代御三家，没选的可以在其他人世界抓 | J22: S1
F23: 天分 | G23: 捕捉1只了不起天分的精灵 | H23: 0 | J23: S1
F24: 进化 | G24: 使精灵成功进化1次 | H24: 0 | I24: 16级进化 | J24: S1
A25: N.006 | B25: 焰火 | C25: 火 | D25: 3 | E25: =SUM(H25:H27)/D25 -> 0 | F25: 捕捉 | G25: 捕捉1只精灵 | H25: 0 | I25: 一代御三家，没选的可以在其他人世界抓 | J25: S1
F26: 天分 | G26: 捕捉1只了不起天分的精灵 | H26: 0 | J26: S1
F27: 进化 | G27: 使精灵成功进化1次 | H27: 0 | I27: 36级进化 | J27: S1
A28: N.007 | B28: 火神 | C28: 火 | D28: 7 | E28: =SUM(H28:H34)/D28 -> 0 | F28: 捕捉 | G28: 捕捉1只精灵 | H28: 0 | I28: 一代御三家，没选的可以在其他人世界抓 | J28: S1
F29: 天分 | G29: 捕捉1只了不起天分的精灵 | H29: 0 | J29: S1
F30: 炫彩 | G30: 捕捉1只炫彩突变的精灵 | H30: 0 | J30: S1
F31: 首领 | G31: 使用进化之力，将精灵进化为首领 | H31: 0 | I31: 完成魔法学院初始精灵首领挑战，获得首领信物「熔炼之火」 | J31: S1
F32: 奖牌 | G32: 获得「命定勇者」奖牌 | H32: 0 | J32: S1
F33: 技能 | G33: 使用2次【怒火】 | H33: 0 | J33: S1
F34: 技能 | G34: 使用2次【持续高温】 | H34: 0 | J34: S1
A35: N.008 | B35: 水蓝蓝 | C35: 水 | D35: 3 | E35: =SUM(H35:H37)/D35 -> 0 | F35: 捕捉 | G35: 捕捉1只精灵 | H35: 0 | I35: 一代御三家，没选的可以在其他人世界抓 | J35: S1
F36: 天分 | G36: 捕捉1只了不起天分的精灵 | H36: 0 | J36: S1
F37: 进化 | G37: 使精灵成功进化1次 | H37: 0 | I37: 16级进化 | J37: S1
A38: N.009 | B38: 波波拉 | C38: 水 | D38: 3 | E38: =SUM(H38:H40)/D38 -> 0 | F38: 捕捉 | G38: 捕捉1只精灵 | H38: 0 | I38: 一代御三家，没选的可以在其他人世界抓 | J38: S1
F39: 天分 | G39: 捕捉1只了不起天分的精灵 | H39: 0 | J39: S1
F40: 进化 | G40: 使精灵成功进化1次 | H40: 0 | I40: 36级进化 | J40: S1
...

Sheet 技能石进度
A1: 精灵编号 | B1: 精灵名称 | C1: 系别 | D1: 技能名称 | E1: 要求次数 | F1: 完成情况 | G1: 完成进度
A2: N.001 | B2: 迪莫 | C2: 光 | D2: 闪光 | E2: 1 | F2: 0 | G2: 0
A3: N.001 | B3: 迪莫 | C3: 光 | D3: 光刃 | E3: 1 | F3: 0 | G3: 0
A4: N.004 | B4: 魔力猫 | C4: 草 | D4: 棘突 | E4: 2 | F4: 0 | G4: 0
A5: N.004 | B5: 魔力猫 | C5: 草 | D5: 光合作用 | E5: 3 | F5: 0 | G5: 0
A6: N.007 | B6: 火神 | C6: 火 | D6: 怒火 | E6: 2 | F6: 0 | G6: 0
A7: N.007 | B7: 火神 | C7: 火 | D7: 持续高温 | E7: 2 | F7: 0 | G7: 0
A8: N.010 | B8: 水灵 | C8: 水 | D8: 水泡 | E8: 2 | F8: 0 | G8: 0
A9: N.010 | B9: 水灵 | C9: 水 | D9: 潮汐 | E9: 2 | F9: 0 | G9: 0
A10: N.011 | B10: 鸭吉吉 | C10: 普通 | D10: 防御 | E10: 1 | F10: 0 | G10: 0
A11: N.011 | B11: 鸭吉吉 | C11: 普通 | D11: 吓退 | E11: 1 | F11: 0 | G11: 0
A12: N.011 | B12: 鸭吉吉 | C12: 普通 | D12: 伺机而动 | E12: 1 | F12: 0 | G12: 0
A13: N.014 | B13: 水泡壳 | C13: 水 | D13: 肥皂泡 | E13: 1 | F13: 0 | G13: 0
... A450: N.439 | B450: 壳栗丝鼠 | C450: 毒 | D450: 溶解 | E450: 2 | F450: 0 | G450: 0

Sheet 技能石进度Excel版
A1: 精灵编号 | B1: 精灵名称 | C1: 系别 | D1: 技能课题 | E1: 技能名称 | F1: 完成情况 | G1: 要求次数 | H1: 技能释放次数 | I1: 完成进度
A2: N.001 | B2: 迪莫 | C2: 光 | D2: 使用1次【闪光】 | E2: 闪光 | F2: =IF(_xlfn.XLOOKUP(D2,课题进度!G:G,课题进度!H:H)=1,"是","否") -> 否 | G2: 1 | I2: =H2/G2 -> 0
A3: N.001 | B3: 迪莫 | C3: 光 | D3: 使用1次【光刃】 | E3: 光刃 | F3: =IF(_xlfn.XLOOKUP(D3,课题进度!G:G,课题进度!H:H)=1,"是","否") -> 否 | G3: 1 | I3: =H3/G3 -> 0
A4: N.004 | B4: 魔力猫 | C4: 草 | D4: 使用2次【棘突】 | E4: 棘突 | F4: =IF(_xlfn.XLOOKUP(D4,课题进度!G:G,课题进度!H:H)=1,"是","否") -> 否 | G4: 2 | I4: =H4/G4 -> 0
A5: N.004 | B5: 魔力猫 | C5: 草 | D5: 使用3次【光合作用】 | E5: 光合作用 | F5: =IF(_xlfn.XLOOKUP(D5,课题进度!G:G,课题进度!H:H)=1,"是","否") -> 否 | G5: 3 | I5: =H5/G5 -> 0
A6: N.007 | B6: 火神 | C6: 火 | D6: 使用2次【怒火】 | E6: 怒火 | F6: =IF(_xlfn.XLOOKUP(D6,课题进度!G:G,课题进度!H:H)=1,"是","否") -> 否 | G6: 2 | I6: =H6/G6 -> 0
A7: N.007 | B7: 火神 | C7: 火 | D7: 使用2次【持续高温】 | E7: 持续高温 | F7: =IF(_xlfn.XLOOKUP(D7,课题进度!G:G,课题进度!H:H)=1,"是","否") -> 否 | G7: 2 | I7: =H7/G7 -> 0
A8: N.010 | B8: 水灵 | C8: 水 | D8: 使用2次【水泡】 | E8: 水泡 | F8: =IF(_xlfn.XLOOKUP(D8,课题进度!G:G,课题进度!H:H)=1,"是","否") -> 否 | G8: 2 | I8: =H8/G8 -> 0
A9: N.010 | B9: 水灵 | C9: 水 | D9: 使用2次【潮汐】 | E9: 潮汐 | F9: =IF(_xlfn.XLOOKUP(D9,课题进度!G:G,课题进度!H:H)=1,"是","否") -> 否 | G9: 2 | I9: =H9/G9 -> 0
A10: N.011 | B10: 鸭吉吉 | C10: 普通 | D10: 使用1次【防御】 | E10: 防御 | F10: =IF(_xlfn.XLOOKUP(D10,课题进度!G:G,课题进度!H:H)=1,"是","否") -> 否 | G10: 1 | I10: =H10/G10 -> 0
A11: N.011 | B11: 鸭吉吉 | C11: 普通 | D11: 使用1次【吓退】 | E11: 吓退 | F11: =IF(_xlfn.XLOOKUP(D11,课题进度!G:G,课题进度!H:H)=1,"是","否") -> 否 | G11: 1 | I11: =H11/G11 -> 0
A12: N.011 | B12: 鸭吉吉 | C12: 普通 | D12: 使用1次【伺机而动】 | E12: 伺机而动 | F12: =IF(_xlfn.XLOOKUP(D12,课题进度!G:G,课题进度!H:H)=1,"是","否") -> 否 | G12: 1 | I12: =H12/G12 -> 0
A13: N.014 | B13: 水泡壳 | C13: 水 | D13: 使用1次【肥皂泡】 | E13: 肥皂泡 | F13: =IF(_xlfn.XLOOKUP(D13,课题进度!G:G,课题进度!H:H)=1,"是","否") -> 否 | G13: 1 | I13: =H13/G13 -> 0
... A450: N.439 | B450: 壳栗丝鼠 | C450: 毒 | D450: 使用2次【溶解】 | E450: 溶解 | F450: =IF(_xlfn.XLOOKUP(D450,课题进度!G:G,课题进度!H:H)=1,"是","否") -> 否 | G450: 2 | I450: =H450/G450 -> 0

Sheet 多地区形态进度
A1: 精灵编号 | B1: 精灵名称 | C1: 形态种类 | D1: 形态名称 | E1: 捕捉方式 | F1: 完成情况 | G1: 完成进度 | H1: 完整进化链 | I1: 备注
A2: N.011 | B2: 鸭吉吉 | C2: 6 | D2: 蓬松的样子 | E2: 地图捕捉，果实放在缺少深水、两栖环境的眠枭庇护所里（提示可能改变精灵形态） | F2: 0 | G2: =(F2+F3)/2 -> 0 | H2: =_xlfn.DISPIMG("ID_B389F0D03A2740CEB75475055365876B",1) -> =DISPIMG("ID_B389F0D03A2740CEB75475055365876B",1) | I2: 鸭吉吉的形态课题只计算两种 | K2: 果实放入后会改变形态的眠枭庇护所可以参考dy：永夜（dy号：34087808366）
D3: 紧实的样子 | E3: 地图捕捉，果实放在有深水、两栖环境的眠枭庇护所里（不提示可能改变精灵形态） | F3: 0 | K3: 地图上具体的捕捉点位可以参考xhs：@小橙子环游记 的笔记
D4: 急急急鸦 | E4: 一测有果实，或别人送的蛋孵化 | F4: 0 | K4: 所有的首领化都只有一种样子，完成进化链需要所有形态都首领化
D5: 等一等鸭 | E5: 二测有果实，或别人送的蛋孵化 | F5: 0
D6: 起来鸭 | E6: 三测有果实，或别人送的蛋孵化 | F6: 0
D7: 燃了鸭 | E7: 公测礼有果实 | F7: 0
A8: N.012 | B8: 板板壳 | C8: 2 | D8: 本来的样子 | E8: 地图捕捉 | F8: 0 | G8: =SUM(F8:F9)/C8 -> 0 | H8: =_xlfn.DISPIMG("ID_8ED7E02B13BF47ADA9E74145185451B0",1) -> =DISPIMG("ID_8ED7E02B13BF47ADA9E74145185451B0",1)
D9: 蜕皮时的样子 | E9: 地图捕捉，圣羽祭台的魔力之源附近；果实放入特定眠枭庇护所后可捕捉（提示可能改变精灵形态） | F9: 0
A10: N.013 | B10: 咔咔壳 | C10: 2 | D10: 本来的样子 | E10: 地图捕捉 | F10: 0 | G10: =SUM(F10:F11)/C10 -> 0
D11: 蜕皮时的样子 | E11: 地图捕捉，圣羽祭台的魔力之源附近；果实放入特定眠枭庇护所后可捕捉（提示可能改变精灵形态） | F11: 0
A12: N.014 | B12: 水泡壳 | C12: 2 | D12: 本来的样子 | E12: 地图捕捉 | F12: 0 | G12: =SUM(F12:F13)/C12 -> 0
D13: 蜕皮时的样子 | E13: 地图捕捉，圣羽祭台的魔力之源附近；果实放入特定眠枭庇护所后可捕捉（提示可能改变精灵形态） | F13: 0
A14: N.018 | B14: 雪绒鸟 | C14: 4 | D14: 本来的样子 | E14: 开局就要捕捉，地图捕捉 | F14: 0 | G14: =SUM(F14:F17)/C14 -> 0 | H14: =_xlfn.DISPIMG("ID_CEA9A08060EC4518A7DD3845924CB37B",1) -> =DISPIMG("ID_CEA9A08060EC4518A7DD3845924CB37B",1) | I14: 挑战精灵首领·霜翼领主后，可以随机获得其中一种样子的蛋；离岚语峰西侧的魔力之源最近的炼金釜旁边有个抽奖机，每个抽屉对应一种样子（1号抽屉-秋天的样子，2号抽屉-春天的样子，3号抽屉-夏天的样子，4号抽屉-冬天的样子）
D15: 秋天的样子 | E15: 地图捕捉 | F15: 0
D16: 春天的样子 | E16: 地图捕捉 | F16: 0
D17: 夏天的样子 | E17: 果实放入特定眠枭庇护所后可捕捉（提示可能改变精灵形态），或者用蛋孵化 | F17: 0
A18: N.019 | B18: 冬羽雀 | C18: 4 | D18: 本来的样子 | E18: 地图捕捉 | F18: 0 | G18: =SUM(F18:F21)/C18 -> 0
D19: 秋天的样子 | E19: 地图捕捉 | F19: 0
D20: 春天的样子 | E20: 地图捕捉 | F20: 0
D21: 夏天的样子 | E21: 果实放入特定眠枭庇护所后可捕捉（提示可能改变精灵形态），或者用蛋孵化 | F21: 0
A22: N.020 | B22: 岚鸟 | C22: 4 | D22: 本来的样子 | E22: 地图捕捉 | F22: 0 | G22: =SUM(F22:F25)/C22 -> 0
D23: 秋天的样子 | E23: 地图捕捉 | F23: 0
D24: 春天的样子 | E24: 地图捕捉 | F24: 0
D25: 夏天的样子 | E25: 果实放入特定眠枭庇护所后可捕捉（提示可能改变精灵形态），或者用蛋孵化 | F25: 0
A26: N.024 | B26: 石肤蜥 | C26: 2 | D26: 本来的样子 | E26: 地图捕捉 | F26: 0 | G26: =SUM(F26:F27)/C26 -> 0 | H26: =_xlfn.DISPIMG("ID_7728F506F9404FA496DE1E6840BCEE6A",1) -> =DISPIMG("ID_7728F506F9404FA496DE1E6840BCEE6A",1)
D27: 球球尾巴的样子 | E27: 地图捕捉 | F27: 0
A28: N.025 | B28: 石刺蜥 | C28: 2 | D28: 本来的样子 | E28: 地图捕捉 | F28: 0 | G28: =SUM(F28:F29)/C28 -> 0
D29: 球球尾巴的样子 | E29: 地图捕捉 | F29: 0
A30: N.026 | B30: 石冠王蜥 | C30: 2 | D30: 本来的样子 | E30: 地图捕捉 | F30: 0 | G30: =SUM(F30:F31)/C30 -> 0
D31: 球球尾巴的样子 | E31: 地图捕捉 | F31: 0
A32: N.034 | B32: 化蝶 | C32: 4 | D32: 平常的样子 | E32: 爬爬随机进化 | F32: 0 | G32: =SUM(F32:F35)/C32 -> 0 | H32: =_xlfn.DISPIMG("ID_1EC3084B49B24F8299F3966AD96A449E",1) -> =DISPIMG("ID_1EC3084B49B24F8299F3966AD96A449E",1) | I32: 目前没有研究到化蝶的进化与地点、时间有明确关联，应当是每次进化都有1/4的概率进化为其中一种样子
D33: 幽冥眼的样子 | E33: 爬爬随机进化 | F33: 0
D34: 喵喵的样子 | E34: 爬爬随机进化 | F34: 0
D35: 奇丽花的样子 | E35: 爬爬随机进化 | F35: 0
A36: N.040 | B36: 晶石蜗 | C36: 6 | D36: 西瓜碧玺的样子 | E36: 撞击3次蓝晶碧玺 | F36: 0 | G36: =SUM(F36:F41)/C36 -> 0 | H36: =_xlfn.DISPIMG("ID_8F79F9EC9F3B4A4CA75B1F93C3B421B8",1) -> =DISPIMG("ID_8F79F9EC9F3B4A4CA75B1F93C3B421B8",1) | I36: 具体的矿石点位可以参照各位博主的跑图路线
D37: 莲花刚玉的样子 | E37: 撞击3次紫莲刚玉 | F37: 0
D38: 星彩榴石的样子 | E38: 撞击3次黄石榴石 | F38: 0
D39: 火山琉璃的样子 | E39: 撞击3次黑晶琉璃 | F39: 0
D40: 蓝锥矿的样子 | E40: 撞击3次蓝晶碧玺＋3次紫莲刚玉 | F40: 0
...

Sheet 果实进度
A1: 精灵编号 | B1: 精灵家族 | C1: 果实获取方式 | D1: 备注 | E1: 完成进度 | F1: 需捕捉数量 | G1: 是否已获取 | H1: 1 | I1: 2 | J1: 3 | K1: 4 | L1: 5 | M1: 6 | N1: 7 | O1: 8 | P1: 9 | Q1: 10 | R1: 11 | S1: 12 | T1: 13 | U1: 14 | V1: 15 | W1: 16 | X1: 17 | Y1: 18 | Z1: 19 | AA1: 20
A2: N.001 | B2: 迪莫 | C2: 开局必送 | D2: 唯一的迪莫 | E2: 0 | F2: 1 | G2: 否 | H2: 0 | I2: 0 | J2: 0 | K2: 0 | L2: 0 | M2: 0 | N2: 0 | O2: 0 | P2: 0 | Q2: 0 | R2: 0 | S2: 0 | T2: 0 | U2: 0 | V2: 0 | W2: 0 | X2: 0 | Y2: 0 | Z2: 0 | AA2: 0
A3: N.002-N.004 | B3: 喵喵家族 | C3: 一代御三家 | D3: 开局三选一 | E3: 0 | F3: 1 | G3: 否 | H3: 0 | I3: 0 | J3: 0 | K3: 0 | L3: 0 | M3: 0 | N3: 0 | O3: 0 | P3: 0 | Q3: 0 | R3: 0 | S3: 0 | T3: 0 | U3: 0 | V3: 0 | W3: 0 | X3: 0 | Y3: 0 | Z3: 0 | AA3: 0
A4: N.005-N.007 | B4: 火花家族 | C4: 一代御三家 | D4: 开局三选一 | E4: 0 | F4: 1 | G4: 否 | H4: 0 | I4: 0 | J4: 0 | K4: 0 | L4: 0 | M4: 0 | N4: 0 | O4: 0 | P4: 0 | Q4: 0 | R4: 0 | S4: 0 | T4: 0 | U4: 0 | V4: 0 | W4: 0 | X4: 0 | Y4: 0 | Z4: 0 | AA4: 0
A5: N.008-N.010 | B5: 水蓝蓝家族 | C5: 一代御三家 | D5: 开局三选一 | E5: 0 | F5: 1 | G5: 否 | H5: 0 | I5: 0 | J5: 0 | K5: 0 | L5: 0 | M5: 0 | N5: 0 | O5: 0 | P5: 0 | Q5: 0 | R5: 0 | S5: 0 | T5: 0 | U5: 0 | V5: 0 | W5: 0 | X5: 0 | Y5: 0 | Z5: 0 | AA5: 0
A6: N.011 | B6: 鸭吉吉家族 | C6: 捕捉20只精灵 | D6: 捕捉20只鸭吉吉 | E6: 0 | F6: 20 | G6: 否 | H6: 0 | I6: 0 | J6: 0 | K6: 0 | L6: 0 | M6: 0 | N6: 0 | O6: 0 | P6: 0 | Q6: 0 | R6: 0 | S6: 0 | T6: 0 | U6: 0 | V6: 0 | W6: 0 | X6: 0 | Y6: 0 | Z6: 0 | AA6: 0
A7: N.012-N.014 | B7: 板板壳家族 | C7: 捕捉20只精灵 | D7: 捕捉20只水泡壳 | E7: 0 | F7: 20 | G7: 否 | H7: 0 | I7: 0 | J7: 0 | K7: 0 | L7: 0 | M7: 0 | N7: 0 | O7: 0 | P7: 0 | Q7: 0 | R7: 0 | S7: 0 | T7: 0 | U7: 0 | V7: 0 | W7: 0 | X7: 0 | Y7: 0 | Z7: 0 | AA7: 0
A8: N.015-N.017 | B8: 锥尾羊家族 | C8: 捕捉20只精灵 | D8: 捕捉20只花影羚羊 | E8: 0 | F8: 20 | G8: 否 | H8: 0 | I8: 0 | J8: 0 | K8: 0 | L8: 0 | M8: 0 | N8: 0 | O8: 0 | P8: 0 | Q8: 0 | R8: 0 | S8: 0 | T8: 0 | U8: 0 | V8: 0 | W8: 0 | X8: 0 | Y8: 0 | Z8: 0 | AA8: 0
A9: N.018-N.020 | B9: 雪绒鸟家族 | C9: 捕捉20只精灵 | D9: 捕捉20只岚鸟 | E9: 0 | F9: 20 | G9: 否 | H9: 0 | I9: 0 | J9: 0 | K9: 0 | L9: 0 | M9: 0 | N9: 0 | O9: 0 | P9: 0 | Q9: 0 | R9: 0 | S9: 0 | T9: 0 | U9: 0 | V9: 0 | W9: 0 | X9: 0 | Y9: 0 | Z9: 0 | AA9: 0
A10: N.021-N.023 | B10: 小灵菇家族 | C10: 捕捉20只精灵 | D10: 捕捉20只幻影灵菇 | E10: 0 | F10: 20 | G10: 否 | H10: 0 | I10: 0 | J10: 0 | K10: 0 | L10: 0 | M10: 0 | N10: 0 | O10: 0 | P10: 0 | Q10: 0 | R10: 0 | S10: 0 | T10: 0 | U10: 0 | V10: 0 | W10: 0 | X10: 0 | Y10: 0 | Z10: 0 | AA10: 0
A11: N.024-N.026 | B11: 石肤蜥家族 | C11: 捕捉20只精灵 | D11: 捕捉20只石冠王蜥 | E11: 0 | F11: 20 | G11: 否 | H11: 0 | I11: 0 | J11: 0 | K11: 0 | L11: 0 | M11: 0 | N11: 0 | O11: 0 | P11: 0 | Q11: 0 | R11: 0 | S11: 0 | T11: 0 | U11: 0 | V11: 0 | W11: 0 | X11: 0 | Y11: 0 | Z11: 0 | AA11: 0
A12: N.027-N.029 | B12: 布是石家族 | C12: 捕捉20只精灵 | D12: 捕捉20只布克棱岩 | E12: 0 | F12: 20 | G12: 否 | H12: 0 | I12: 0 | J12: 0 | K12: 0 | L12: 0 | M12: 0 | N12: 0 | O12: 0 | P12: 0 | Q12: 0 | R12: 0 | S12: 0 | T12: 0 | U12: 0 | V12: 0 | W12: 0 | X12: 0 | Y12: 0 | Z12: 0 | AA12: 0
A13: N.030-N.031 | B13: 恶魔叮家族 | C13: 捕捉20只精灵 | D13: 捕捉20只叮叮恶魔 | E13: 0 | F13: 20 | G13: 否 | H13: 0 | I13: 0 | J13: 0 | K13: 0 | L13: 0 | M13: 0 | N13: 0 | O13: 0 | P13: 0 | Q13: 0 | R13: 0 | S13: 0 | T13: 0 | U13: 0 | V13: 0 | W13: 0 | X13: 0 | Y13: 0 | Z13: 0 | AA13: 0
... A178: N.438-N.439 | B178: 栗鼠家族 | C178: 赛季作业·铅字幻梦 | D178: 在赛季奇遇中与栗鼠建立契约 | E178: 0 | F178: 1 | G178: 否 | H178: 0 | I178: 0 | J178: 0 | K178: 0 | L178: 0 | M178: 0 | N178: 0 | O178: 0 | P178: 0 | Q178: 0 | R178: 0 | S178: 0 | T178: 0 | U178: 0 | V178: 0 | W178: 0 | X178: 0 | Y178: 0 | Z178: 0 | AA178: 0

Sheet S2幸运惊喜盒特供
A1: 精灵分类 | B1: 精灵名称 | C1: 对应表述 | D1: 官方提示获取方式
A2: 大世界随机精灵 | B2: - | C2: 盒子正在期待被打开......
A3: 大世界随机精灵 | B3: - | C3: 盒子晃了晃，正在开心的看着你......
A4: 大世界随机精灵 | B4: - | C4: 盒子安静的等待着......
A5: 大世界随机精灵 | B5: - | C5: 盒子轻轻摇动，似乎在和你打招呼......
A6: 大世界随机精灵 | B6: - | C6: 盒子咚咚地敲了两下，像是在试探你的反应......
A7: 赛季奇遇精灵 | B7: 猴麦仔 | C7: 盒子里传来嘹亮的声音，音量听起来像被放大过一样，穿透力十足...... | D7: 系别池，机械系/普通系
A8: 赛季奇遇精灵 | B8: 加油海葵 | C8: 盒子上冒出一圈圈气泡，里面传来柔软触须轻轻摇摆的哗啦声...... | D8: 系别池，水系/萌系
A9: 赛季奇遇精灵 | B9: 小丑豆豆 | C9: 盒子里发出欢快的蹦跳声，偶尔还有咯咯的笑意响动...... | D9: 蛋组池，白发懒人/雪蛮人，红色盒子
A10: 赛季奇遇精灵 | B10: 烟花团 | C10: 一靠近盒子就听到热闹的噼啪声，此起彼伏，接着盒顶冒出了一朵朵小烟花...... | D10: 蛋组池，岚鸟/皇家狮鹫，蓝色盒子
A11: 赛季奇遇精灵 | B11: 咕咕帽 | C11: 盒子里不时喷出一团彩雾，里面似乎在进行什么魔术表演...... | D11: 系别池，幽系
A12: 赛季奇遇精灵 | B12: 炫光迪迪 | C12: 盒子里传来鳞片叮叮当当随着盒子摇动的声音，缝隙里透露出一丝彩光...... | D12: 蛋组池，石肤蜥/矿晶虫，黄色盒子
A13: 赛季奇遇精灵 | B13: 小鼓象 | C13: 盒子里传来啪嗒啪嗒的敲鼓声，伴随着哞哞的轻鸣，节奏感一流...... | D13: 系别池，机械系
A14: 赛季奇遇精灵 | B14: 牵线木偶 | C14: 盒子里显得很安静，偶尔能听到一点吱呀的动作声...... | D14: 系别池，幻系
A15: 非赛季奇遇精灵 | B15: 公平鸽 | C15: 盒子在尝试保持平衡，绝不向任何一边歪斜......
A16: 非赛季奇遇精灵 | B16: 灵狐 | C16: 盒子摸着有些冰冷，但偶尔又有股热气从缝隙里传出，一下把寒冷感驱散了......
A17: 非赛季奇遇精灵 | B17: 独角兽 | C17: 盒子的内壁传来鬃毛拂过的沙沙声，抚摸盒子时似乎感到一阵安心......
A18: 非赛季奇遇精灵 | B18: 嘟嘟锅 | C18: 盒子里发出了咕嘟咕嘟的声音，有什么似乎在沸腾，快要将盒子胀开了......
A19: 非赛季奇遇精灵 | B19: 菊花梨 | C19: 盒子的顶部缝隙里露出了几片花瓣，闻起来像梨子的味道，十分清新......
A20: 非赛季奇遇精灵 | B20: 幽影树 | C20: 盒子里传来树皮摩擦般的窸窣声，感觉到它尝试不发出动静，缺失败了......
A21: 非赛季奇遇精灵 | B21: 小夜 | C21: 盒子里传来一声细微的喵叫，随后听见它快速跃起，在盒子里进行了一番跑酷
A22: 非赛季奇遇精灵 | B22: 恶魔叮 | C22: 盒子的内壁发出砰砰的撞击声，似乎有个圆滚滚的身体在四处乱窜和飞起......
A23: 特殊遭遇 | B23: 果冻 | C23: 盒子里传来果冻般粘腻的、滑滑的声音，正在跟随盒子有节奏地晃动......
A24: 特殊遭遇 | B24: 星尘虫 | C24: 盒子里传来窸窸窣窣的爬行声，伴随一丝星芒从缝隙里掠过......
A25: S1通行证 | B25: 绒绒 | C25: 盒子里传来一阵沙沙声，像细密的绒毛贴过内壁，靠近时感觉它向你蹭了蹭......
A26: S1通行证 | B26: 犀角鸟 | C26: 盒子的侧面某个部位撑开成了犀角状，缝隙里还漏出了一撮毛发......
... A28: S2通行证 | B28: 爆焰仔 | C28: 盒子里传出火焰噼啪的闷响，某处热的发烫，似乎随时要爆出焰火......

Sheet S3精灵童话书特供
A1: 特长分类 | B1: 特长名称 | C1: 对应表述
A2: 不具备特长 | B2: - | C2: 线团上描绘着它安静发呆的样子......
A3: 不具备特长 | B3: - | C3: 线团上勾勒着它一摇一摆的样子......
A4: 不具备特长 | B4: - | C4: 线团上描画着它歪着头的样子......
A5: 具备特长 | B5: 爱分享 | C5: 线团上描绘着它正开心地向洛克分享着什么的样子......
A6: 具备特长 | B6: 同乘 | C6: 线团上依稀能看到它轻松地载着两位洛克旅行的样子......
A7: 具备特长 | B7: 疾行 | C7: 线团上勾勒了几团扬起的风卷，以及因跑动而模糊的线条......
A8: 具备特长 | B8: 热心教 | C8: 线团上依稀能看到它热心地和同伴分享着胜利经验的样子......
A9: 具备特长 | B9: 亲密 | C9: 线团上描画着它把脑袋往小洛克手心钻，亲密地蹭了蹭的样子......
A10: 具备特长 | B10: 灵巧 | C10: 线团上描画着它专心为小洛克搜寻着远处的好东西的样子......
A11: 具备特长 | B11: 奇袭 | C11: 线团上勾勒着它在眨眼的刹那，向着敌人背部出击的样子......
A12: 具备特长 | B12: 家里蹲 | C12: 线团上勾勒着它在最爱的舒适角落里散发灵感的样子......
... A17: 血脉提示 | B17: 奇异血脉 | C17: 小加尔想了想，染上了几笔奇异的颜色！

Sheet 精灵蛋收集进度
A1: 精灵编号 | B1: 精灵家族 | C1: 系别 | D1: 形态/异色 | E1: 蛋组 | F1: 是否收集 | G1: 母本（生蛋用） | H1: 特殊获取途径或备注
A2: N.001 | B2: 迪莫 | C2: 光 | D2: - | E2: 无法生蛋 | F2: 0 | G2: 0 | H2: 所有精灵蛋没有特殊说明的均来源于洛克王国BWIKI，地区样式能否生蛋科研结果xhs：@浮生
A3: N.002-N.004 | B3: 喵喵家族 | C3: 草 | D3: - | E3: 动物组,拟人组 | F3: 0 | G3: 0
A4: N.005-N.007 | B4: 火花家族 | C4: 火 | D4: - | E4: 巨灵组,魔力组 | F4: 0 | G4: 0
A5: N.008-N.010 | B5: 水蓝蓝家族 | C5: 水 | D5: - | E5: 魔力组 | F5: 0 | G5: 0
A6: N.011 | B6: 鸭吉吉家族 | C6: 普通 | D6: 蓬松的样子 | E6: 天空组 | F6: 0 | G6: 0
A7: N.011 | B7: 鸭吉吉家族 | C7: 普通 | D7: 紧实的样子 | E7: 天空组 | F7: 0 | G7: 0
A8: N.011 | B8: 鸭吉吉家族 | C8: 普通 | D8: 急急急鸦 | E8: 天空组 | F8: 0 | G8: 0 | H8: 一测
A9: N.011 | B9: 鸭吉吉家族 | C9: 普通 | D9: 等一等鸭 | E9: 天空组 | F9: 0 | G9: 0 | H9: 二测
A10: N.011 | B10: 鸭吉吉家族 | C10: 普通 | D10: 起来鸭 | E10: 天空组 | F10: 0 | G10: 0 | H10: 三测
A11: N.011 | B11: 鸭吉吉家族 | C11: 普通 | D11: 燃了鸭 | E11: 天空组 | F11: 0 | G11: 0 | H11: 公测礼
A12: N.012-N.014 | B12: 板板壳家族 | C12: 水 | D12: - | E12: 两栖组 | F12: 0 | G12: 0 | H12: 生蛋只能生出本来的样子，蜕皮时的样子蛋生不出
A13: N.015-N.017 | B13: 锥尾羊家族 | C13: 幽,恶 | D13: - | E13: 动物组 | F13: 0 | G13: 0 | H13: 锥尾羊、铃兰羊幽系，花影羚羊幽系+恶系
A14: N.018-N.020 | B14: 雪绒鸟家族 | C14: 翼 | D14: 本来的样子 | E14: 天空组 | F14: 0 | G14: 0 | H14: 抽奖机，首领随机
A15: N.018-N.020 | B15: 雪绒鸟家族 | C15: 翼 | D15: 秋天的样子 | E15: 天空组 | F15: 0 | G15: 0 | H15: 抽奖机，首领随机
A16: N.018-N.020 | B16: 雪绒鸟家族 | C16: 翼 | D16: 春天的样子 | E16: 天空组 | F16: 0 | G16: 0 | H16: 抽奖机，首领随机
A17: N.018-N.020 | B17: 雪绒鸟家族 | C17: 翼 | D17: 夏天的样子 | E17: 天空组 | F17: 0 | G17: 0 | H17: 抽奖机，首领随机
A18: N.021-N.023 | B18: 小灵菇家族 | C18: 幽,草 | D18: - | E18: 魔力组,植物组 | F18: 0 | G18: 0 | H18: 小灵菇幽系，幻灵菇、幻影灵菇幽系+草系
A19: N.024-N.026 | B19: 石肤蜥家族 | C19: 地 | D19: - | E19: 两栖组,大地组 | F19: 0 | G19: 0 | H19: 生蛋只能生出本来的样子，球球尾巴的样子蛋生不出
A20: N.027-N.029 | B20: 布是石家族 | C20: 地 | D20: - | E20: 巨灵组,大地组 | F20: 0 | G20: 0 | H20: 首领
A21: N.030-N.031 | B21: 恶魔叮家族 | C21: 恶,翼 | D21: 原色 | E21: 妖精组 | F21: 0 | G21: 0
A22: N.030-N.031 | B22: 恶魔叮家族 | C22: 恶,翼 | D22: 异色 | E22: 妖精组 | F22: 0 | G22: 0 | H22: S2，家园或礼包概率出
A23: N.032-N.034 | B23: 毛毛家族 | C23: 虫,萌 | D23: - | E23: 昆虫组,软体组 | F23: 0 | G23: 0 | H23: 化蝶阶段分化，蛋是一样的
A24: N.035 | B24: 幽影树家族 | C24: 幽,草 | D24: 原色 | E24: 植物组 | F24: 0 | G24: 0
A25: N.035 | B25: 幽影树家族 | C25: 幽,草 | D25: 异色 | E25: 植物组 | F25: 0 | G25: 0 | H25: S2，家园或礼包概率出
A26: N.036-N.038 | B26: 小鼠獭家族 | C26: 普通,水 | D26: - | E26: 动物组,两栖组 | F26: 0 | G26: 0
A27: N.039-N.040 | B27: 矿晶虫家族 | C27: 光,地 | D27: - | E27: 大地组,软体组 | F27: 0 | G27: 0 | H27: 晶石蜗阶段分化，蛋是一样的
A28: N.041-N.043 | B28: 奇丽草家族 | C28: 草 | D28: 原色 | E28: 植物组 | F28: 0 | G28: 0
A29: N.041-N.043 | B29: 奇丽草家族 | C29: 草 | D29: 异色 | E29: 植物组 | F29: 0 | G29: 0 | H29: S1，家园或礼包概率出
A30: N.044-N.046 | B30: 丢丢家族 | C30: 草 | D30: 沙地附近的样子 | E30: 两栖组 | F30: 0 | G30: 0
A31: N.044-N.046 | B31: 丢丢家族 | C31: 草 | D31: 草地附近的样子 | E31: 两栖组 | F31: 0 | G31: 0
A32: N.044-N.046 | B32: 丢丢家族 | C32: 草 | D32: 雪山附近的样子 | E32: 两栖组 | F32: 0 | G32: 0
A33: N.047-N.048 | B33: 护主犬家族 | C33: 火 | D33: - | E33: 动物组 | F33: 0 | G33: 0 | H33: 首领
A34: N.049-N.051 | B34: 绿耳松鼠家族 | C34: 普通 | D34: - | E34: 动物组 | F34: 0 | G34: 0
A35: N.052-N.053 | B35: 嘟嘟煲家族 | C35: 毒 | D35: 原色 | E35: 大地组,妖精组 | F35: 0 | G35: 0
A36: N.052-N.053 | B36: 嘟嘟煲家族 | C36: 毒 | D36: 异色 | E36: 大地组,妖精组 | F36: 0 | G36: 0 | H36: S2，家园或礼包概率出
A37: N.054-N.056 | B37: 小灵面家族 | C37: 幽 | D37: - | E37: 魔力组 | F37: 0 | G37: 0 | H37: 暗影灵面阶段分化，蛋是一样的
A38: N.057-N.058 | B38: 梦游家族 | C38: 幽 | D38: - | E38: 魔力组,妖精组 | F38: 0 | G38: 0
A39: N.059 | B39: 兽花蕾家族 | C39: 光,草 | D39: - | E39: 植物组 | F39: 0 | G39: 0
A40: N.060-N.062 | B40: 伏地兽家族 | C40: 普通 | D40: - | E40: 动物组 | F40: 0 | G40: 0
...
